<?xml version="1.0" encoding="UTF-8" standalone="no"?>
<?pydev-testrun version="1.0"?><pydev-testsuite>
<summary errors="0" failures="1" finished="true" name="Test Run: 41" tests="1" total_time="Finished in: 23.11 secs."/>
<test location="/Users/apple/Documents/workspace/django_program/superlists/functional_tests.py" status="fail" test="NewVisitorTest.test_can_start_a_list_and_retrieve_it_later" time="">
<stdout/>
<stderr><![CDATA[Traceback (most recent call last):
  File "/Users/apple/Documents/workspace/django_program/superlists/functional_tests.py", line 45, in test_can_start_a_list_and_retrieve_it_later
    "New to-do item did not appear in table--its text was:\n%s" %(table.text,))
AssertionError: False is not true : New to-do item did not appear in table--its text was:
Buy peacock feathers
]]></stderr>
</test>
<launch mode="run">
<launch_memento><![CDATA[<?xml version="1.0" encoding="UTF-8" standalone="no"?>
<launchConfiguration local="true" path="django_program functional_tests.py (1)"/>
]]></launch_memento>
</launch>
</pydev-testsuite>
